Workbook
Name Slicer_CampaignChannel: #N/A
Name Slicer_CampaignType: #N/A
Name Slicer_Gender: #N/A
Name Slicer_Income_Group: #N/A

Sheet Customer analytics
A1: CustomerID | B1: Age | C1: Gender | D1: Income | E1: Income Group | F1: WebsiteVisits | G1: PagesPerVisit | H1: TimeOnSite | I1: Time on Site Group | J1: SocialShares | K1: EmailOpens | L1: EmailClicks | M1: PreviousPurchases | N1: LoyaltyPoints | O1: Conversion
A2: 8004 | B2: 60 | C2: Female | D2: 83964 | E2: =IF(Customer_analytics[[#This Row],[Income]]<50000, "Low", IF(Customer_analytics[[#This Row],[Income]]<100000, "Mid", "High")) -> Mid | F2: 0 | G2: 2.05 | H2: 13.99 | I2: =IF(Customer_analytics[[#This Row],[TimeOnSite]]<3, "Short Visit", IF(Customer_analytics[[#This Row],[TimeOnSite]]<7, "Medium Visit", "Long Visit")) -> Long Visit | J2: 6 | K2: 6 | L2: 6 | M2: 8 | N2: 4345 | O2: 1
A3: 8006 | B3: 38 | C3: Female | D3: 25615 | E3: =IF(Customer_analytics[[#This Row],[Income]]<50000, "Low", IF(Customer_analytics[[#This Row],[Income]]<100000, "Mid", "High")) -> Low | F3: 42 | G3: 1.75 | H3: 10.7 | I3: =IF(Customer_analytics[[#This Row],[TimeOnSite]]<3, "Short Visit", IF(Customer_analytics[[#This Row],[TimeOnSite]]<7, "Medium Visit", "Long Visit")) -> Long Visit | J3: 54 | K3: 14 | L3: 3 | M3: 6 | N3: 930 | O3: 1
A4: 8012 | B4: 41 | C4: Male | D4: 131093 | E4: =IF(Customer_analytics[[#This Row],[Income]]<50000, "Low", IF(Customer_analytics[[#This Row],[Income]]<100000, "Mid", "High")) -> High | F4: 13 | G4: 8.89 | H4: 8.48 | I4: =IF(Customer_analytics[[#This Row],[TimeOnSite]]<3, "Short Visit", IF(Customer_analytics[[#This Row],[TimeOnSite]]<7, "Medium Visit", "Long Visit")) -> Long Visit | J4: 28 | K4: 16 | L4: 5 | M4: 4 | N4: 2946 | O4: 1
A5: 8013 | B5: 53 | C5: Male | D5: 64608 | E5: =IF(Customer_analytics[[#This Row],[Income]]<50000, "Low", IF(Customer_analytics[[#This Row],[Income]]<100000, "Mid", "High")) -> Mid | F5: 8 | G5: 8.5 | H5: 14.25 | I5: =IF(Customer_analytics[[#This Row],[TimeOnSite]]<3, "Short Visit", IF(Customer_analytics[[#This Row],[TimeOnSite]]<7, "Medium Visit", "Long Visit")) -> Long Visit | J5: 81 | K5: 8 | L5: 1 | M5: 2 | N5: 2818 | O5: 1
A6: 8014 | B6: 57 | C6: Male | D6: 148788 | E6: =IF(Customer_analytics[[#This Row],[Income]]<50000, "Low", IF(Customer_analytics[[#This Row],[Income]]<100000, "Mid", "High")) -> High | F6: 20 | G6: 7.36 | H6: 2.47 | I6: =IF(Customer_analytics[[#This Row],[TimeOnSite]]<3, "Short Visit", IF(Customer_analytics[[#This Row],[TimeOnSite]]<7, "Medium Visit", "Long Visit")) -> Short Visit | J6: 70 | K6: 16 | L6: 8 | M6: 1 | N6: 3247 | O6: 1
A7: 8015 | B7: 41 | C7: Female | D7: 39192 | E7: =IF(Customer_analytics[[#This Row],[Income]]<50000, "Low", IF(Customer_analytics[[#This Row],[Income]]<100000, "Mid", "High")) -> Low | F7: 44 | G7: 6.95 | H7: 2.25 | I7: =IF(Customer_analytics[[#This Row],[TimeOnSite]]<3, "Short Visit", IF(Customer_analytics[[#This Row],[TimeOnSite]]<7, "Medium Visit", "Long Visit")) -> Short Visit | J7: 33 | K7: 0 | L7: 1 | M7: 1 | N7: 4474 | O7: 0
A8: 8018 | B8: 19 | C8: Female | D8: 117392 | E8: =IF(Customer_analytics[[#This Row],[Income]]<50000, "Low", IF(Customer_analytics[[#This Row],[Income]]<100000, "Mid", "High")) -> High | F8: 7 | G8: 3.12 | H8: 8.44 | I8: =IF(Customer_analytics[[#This Row],[TimeOnSite]]<3, "Short Visit", IF(Customer_analytics[[#This Row],[TimeOnSite]]<7, "Medium Visit", "Long Visit")) -> Long Visit | J8: 92 | K8: 8 | L8: 4 | M8: 6 | N8: 2222 | O8: 1
A9: 8019 | B9: 41 | C9: Female | D9: 69949 | E9: =IF(Customer_analytics[[#This Row],[Income]]<50000, "Low", IF(Customer_analytics[[#This Row],[Income]]<100000, "Mid", "High")) -> Mid | F9: 35 | G9: 9.82 | H9: 1.9 | I9: =IF(Customer_analytics[[#This Row],[TimeOnSite]]<3, "Short Visit", IF(Customer_analytics[[#This Row],[TimeOnSite]]<7, "Medium Visit", "Long Visit")) -> Short Visit | J9: 36 | K9: 7 | L9: 7 | M9: 3 | N9: 3644 | O9: 1
A10: 8027 | B10: 39 | C10: Male | D10: 98311 | E10: =IF(Customer_analytics[[#This Row],[Income]]<50000, "Low", IF(Customer_analytics[[#This Row],[Income]]<100000, "Mid", "High")) -> Mid | F10: 39 | G10: 2.52 | H10: 9.33 | I10: =IF(Customer_analytics[[#This Row],[TimeOnSite]]<3, "Short Visit", IF(Customer_analytics[[#This Row],[TimeOnSite]]<7, "Medium Visit", "Long Visit")) -> Long Visit | J10: 98 | K10: 17 | L10: 6 | M10: 1 | N10: 2688 | O10: 1
A11: 8028 | B11: 61 | C11: Female | D11: 27549 | E11: =IF(Customer_analytics[[#This Row],[Income]]<50000, "Low", IF(Customer_analytics[[#This Row],[Income]]<100000, "Mid", "High")) -> Low | F11: 25 | G11: 3.95 | H11: 10.67 | I11: =IF(Customer_analytics[[#This Row],[TimeOnSite]]<3, "Short Visit", IF(Customer_analytics[[#This Row],[TimeOnSite]]<7, "Medium Visit", "Long Visit")) -> Long Visit | J11: 92 | K11: 17 | L11: 1 | M11: 3 | N11: 68 | O11: 1
A12: 8032 | B12: 59 | C12: Female | D12: 43958 | E12: =IF(Customer_analytics[[#This Row],[Income]]<50000, "Low", IF(Customer_analytics[[#This Row],[Income]]<100000, "Mid", "High")) -> Low | F12: 24 | G12: 3.17 | H12: 3.14 | I12: =IF(Customer_analytics[[#This Row],[TimeOnSite]]<3, "Short Visit", IF(Customer_analytics[[#This Row],[TimeOnSite]]<7, "Medium Visit", "Long Visit")) -> Medium Visit | J12: 24 | K12: 10 | L12: 5 | M12: 6 | N12: 4683 | O12: 1
A13: 8039 | B13: 69 | C13: Male | D13: 141835 | E13: =IF(Customer_analytics[[#This Row],[Income]]<50000, "Low", IF(Customer_analytics[[#This Row],[Income]]<100000, "Mid", "High")) -> High | F13: 20 | G13: 1.7 | H13: 1.17 | I13: =IF(Customer_analytics[[#This Row],[TimeOnSite]]<3, "Short Visit", IF(Customer_analytics[[#This Row],[TimeOnSite]]<7, "Medium Visit", "Long Visit")) -> Short Visit | J13: 1 | K13: 13 | L13: 0 | M13: 0 | N13: 2885 | O13: 1
... A319: 11432 | B319: 28 | C319: Female | D319: 23582 | E319: =IF(Customer_analytics[[#This Row],[Income]]<50000, "Low", IF(Customer_analytics[[#This Row],[Income]]<100000, "Mid", "High")) -> Low | F319: 39 | G319: 4.22 | H319: 3.47 | I319: =IF(Customer_analytics[[#This Row],[TimeOnSite]]<3, "Short Visit", IF(Customer_analytics[[#This Row],[TimeOnSite]]<7, "Medium Visit", "Long Visit")) -> Medium Visit | J319: 0 | K319: 7 | L319: 9 | M319: 6 | N319: 1953 | O319: 1

Sheet Marketing dataset
A1: CustomerID | B1: CampaignChannel | C1: CampaignType | D1: AdSpend | E1: ClickThroughRate | F1: ConversionRate | G1: WebsiteVisits | H1: SocialShares | I1: EmailOpens | J1: EmailClicks | K1: AdvertisingPlatform | L1: AdvertisingTool | M1: Conversion
A2: 8004 | B2: PPC | C2: Conversion | D2: 1678.04 | E2: 0.25 | F2: 0.11 | G2: 0 | H2: 6 | I2: 6 | J2: 6 | K2: IsConfid | L2: ToolConfid | M2: 1
A3: 8006 | B3: Referral | C3: Awareness | D3: 7302.9 | E3: 0.04 | F3: 0.06 | G3: 42 | H3: 54 | I3: 14 | J3: 3 | K3: IsConfid | L3: ToolConfid | M3: 1
A4: 8012 | B4: Email | C4: Conversion | D4: 5930.92 | E4: 0.22 | F4: 0.02 | G4: 13 | H4: 28 | I4: 16 | J4: 5 | K4: IsConfid | L4: ToolConfid | M4: 1
A5: 8013 | B5: SEO | C5: Awareness | D5: 1520.42 | E5: 0.19 | F5: 0.16 | G5: 8 | H5: 81 | I5: 8 | J5: 1 | K5: IsConfid | L5: ToolConfid | M5: 1
A6: 8014 | B6: Email | C6: Awareness | D6: 4104.38 | E6: 0.12 | F6: 0.11 | G6: 20 | H6: 70 | I6: 16 | J6: 8 | K6: IsConfid | L6: ToolConfid | M6: 1
A7: 8015 | B7: Email | C7: Awareness | D7: 429.08 | E7: 0.07 | F7: 0.1 | G7: 44 | H7: 33 | I7: 0 | J7: 1 | K7: IsConfid | L7: ToolConfid | M7: 0
A8: 8018 | B8: PPC | C8: Conversion | D8: 3939.01 | E8: 0.15 | F8: 0.03 | G8: 7 | H8: 92 | I8: 8 | J8: 4 | K8: IsConfid | L8: ToolConfid | M8: 1
A9: 8019 | B9: PPC | C9: Consideration | D9: 8446.05 | E9: 0.3 | F9: 0.05 | G9: 35 | H9: 36 | I9: 7 | J9: 7 | K9: IsConfid | L9: ToolConfid | M9: 1
A10: 8027 | B10: Social Media | C10: Retention | D10: 6920.24 | E10: 0.01 | F10: 0.11 | G10: 39 | H10: 98 | I10: 17 | J10: 6 | K10: IsConfid | L10: ToolConfid | M10: 1
A11: 8028 | B11: Referral | C11: Retention | D11: 6250.27 | E11: 0.15 | F11: 0.08 | G11: 25 | H11: 92 | I11: 17 | J11: 1 | K11: IsConfid | L11: ToolConfid | M11: 1
A12: 8032 | B12: Referral | C12: Awareness | D12: 8740.45 | E12: 0.28 | F12: 0.02 | G12: 24 | H12: 24 | I12: 10 | J12: 5 | K12: IsConfid | L12: ToolConfid | M12: 1
A13: 8039 | B13: Referral | C13: Conversion | D13: 3360.96 | E13: 0.13 | F13: 0.16 | G13: 20 | H13: 1 | I13: 13 | J13: 0 | K13: IsConfid | L13: ToolConfid | M13: 1
... A319: 11432 | B319: SEO | C319: Retention | D319: 8207.87 | E319: 0.1 | F319: 0.15 | G319: 39 | H319: 0 | I319: 7 | J319: 9 | K319: IsConfid | L319: ToolConfid | M319: 1

Sheet digital_marketing_campaign_data
A1: CustomerID | B1: Age | C1: Gender | D1: Income | E1: CampaignChannel | F1: CampaignType | G1: AdSpend | H1: ClickThroughRate | I1: ConversionRate | J1: WebsiteVisits | K1: PagesPerVisit | L1: TimeOnSite | M1: SocialShares | N1: EmailOpens | O1: EmailClicks | P1: PreviousPurchases | Q1: LoyaltyPoints | R1: AdvertisingPlatform | S1: AdvertisingTool | T1: Conversion | U1: CPA
A2: 8004 | B2: 60 | C2: Female | D2: 83964 | E2: PPC | F2: Conversion | G2: 1678.04 | H2: 0.25 | I2: 0.11 | J2: 0 | K2: 2.05 | L2: 13.99 | M2: 6 | N2: 6 | O2: 6 | P2: 8 | Q2: 4345 | R2: IsConfid | S2: ToolConfid | T2: 1 | U2: 1678.04
A3: 8006 | B3: 38 | C3: Female | D3: 25615 | E3: Referral | F3: Awareness | G3: 7302.9 | H3: 0.04 | I3: 0.06 | J3: 42 | K3: 1.75 | L3: 10.7 | M3: 54 | N3: 14 | O3: 3 | P3: 6 | Q3: 930 | R3: IsConfid | S3: ToolConfid | T3: 1 | U3: 7302.9
A4: 8012 | B4: 41 | C4: Male | D4: 131093 | E4: Email | F4: Conversion | G4: 5930.92 | H4: 0.22 | I4: 0.02 | J4: 13 | K4: 8.89 | L4: 8.48 | M4: 28 | N4: 16 | O4: 5 | P4: 4 | Q4: 2946 | R4: IsConfid | S4: ToolConfid | T4: 1 | U4: 5930.92
A5: 8013 | B5: 53 | C5: Male | D5: 64608 | E5: SEO | F5: Awareness | G5: 1520.42 | H5: 0.19 | I5: 0.16 | J5: 8 | K5: 8.5 | L5: 14.25 | M5: 81 | N5: 8 | O5: 1 | P5: 2 | Q5: 2818 | R5: IsConfid | S5: ToolConfid | T5: 1 | U5: 1520.42
A6: 8014 | B6: 57 | C6: Male | D6: 148788 | E6: Email | F6: Awareness | G6: 4104.38 | H6: 0.12 | I6: 0.11 | J6: 20 | K6: 7.36 | L6: 2.47 | M6: 70 | N6: 16 | O6: 8 | P6: 1 | Q6: 3247 | R6: IsConfid | S6: ToolConfid | T6: 1 | U6: 4104.38
A7: 8015 | B7: 41 | C7: Female | D7: 39192 | E7: Email | F7: Awareness | G7: 429.08 | H7: 0.07 | I7: 0.1 | J7: 44 | K7: 6.95 | L7: 2.25 | M7: 33 | N7: 0 | O7: 1 | P7: 1 | Q7: 4474 | R7: IsConfid | S7: ToolConfid | T7: 0
A8: 8018 | B8: 19 | C8: Female | D8: 117392 | E8: PPC | F8: Conversion | G8: 3939.01 | H8: 0.15 | I8: 0.03 | J8: 7 | K8: 3.12 | L8: 8.44 | M8: 92 | N8: 8 | O8: 4 | P8: 6 | Q8: 2222 | R8: IsConfid | S8: ToolConfid | T8: 1 | U8: 3939.01
A9: 8019 | B9: 41 | C9: Female | D9: 69949 | E9: PPC | F9: Consideration | G9: 8446.05 | H9: 0.3 | I9: 0.05 | J9: 35 | K9: 9.82 | L9: 1.9 | M9: 36 | N9: 7 | O9: 7 | P9: 3 | Q9: 3644 | R9: IsConfid | S9: ToolConfid | T9: 1 | U9: 8446.05
A10: 8027 | B10: 39 | C10: Male | D10: 98311 | E10: Social Media | F10: Retention | G10: 6920.24 | H10: 0.01 | I10: 0.11 | J10: 39 | K10: 2.52 | L10: 9.33 | M10: 98 | N10: 17 | O10: 6 | P10: 1 | Q10: 2688 | R10: IsConfid | S10: ToolConfid | T10: 1 | U10: 6920.24
A11: 8028 | B11: 61 | C11: Female | D11: 27549 | E11: Referral | F11: Retention | G11: 6250.27 | H11: 0.15 | I11: 0.08 | J11: 25 | K11: 3.95 | L11: 10.67 | M11: 92 | N11: 17 | O11: 1 | P11: 3 | Q11: 68 | R11: IsConfid | S11: ToolConfid | T11: 1 | U11: 6250.27
A12: 8032 | B12: 59 | C12: Female | D12: 43958 | E12: Referral | F12: Awareness | G12: 8740.45 | H12: 0.28 | I12: 0.02 | J12: 24 | K12: 3.17 | L12: 3.14 | M12: 24 | N12: 10 | O12: 5 | P12: 6 | Q12: 4683 | R12: IsConfid | S12: ToolConfid | T12: 1 | U12: 8740.45
A13: 8039 | B13: 69 | C13: Male | D13: 141835 | E13: Referral | F13: Conversion | G13: 3360.96 | H13: 0.13 | I13: 0.16 | J13: 20 | K13: 1.7 | L13: 1.17 | M13: 1 | N13: 13 | O13: 0 | P13: 0 | Q13: 2885 | R13: IsConfid | S13: ToolConfid | T13: 1 | U13: 3360.96
A14: 8040 | B14: 20 | C14: Female | D14: 57538 | E14: Email | F14: Conversion | G14: 4101.22 | H14: 0.28 | I14: 0.1 | J14: 24 | K14: 1.07 | L14: 11.25 | M14: 13 | N14: 4 | O14: 7 | P14: 3 | Q14: 1476 | R14: IsConfid | S14: ToolConfid | T14: 1 | U14: 4101.22
A15: 8041 | B15: 54 | C15: Female | D15: 25833 | E15: Social Media | F15: Conversion | G15: 9087.27 | H15: 0.02 | I15: 0.1 | J15: 39 | K15: 8.78 | L15: 2.34 | M15: 49 | N15: 14 | O15: 3 | P15: 1 | Q15: 3243 | R15: IsConfid | S15: ToolConfid | T15: 1 | U15: 9087.27
A16: 8043 | B16: 24 | C16: Male | D16: 43386 | E16: SEO | F16: Retention | G16: 5705.13 | H16: 0.05 | I16: 0.19 | J16: 21 | K16: 2.29 | L16: 8.55 | M16: 33 | N16: 5 | O16: 9 | P16: 0 | Q16: 913 | R16: IsConfid | S16: ToolConfid | T16: 0
A17: 8045 | B17: 26 | C17: Male | D17: 120349 | E17: Social Media | F17: Awareness | G17: 5036.73 | H17: 0.15 | I17: 0.09 | J17: 7 | K17: 8.66 | L17: 7.88 | M17: 91 | N17: 15 | O17: 3 | P17: 0 | Q17: 284 | R17: IsConfid | S17: ToolConfid | T17: 1 | U17: 5036.73
A18: 8046 | B18: 56 | C18: Female | D18: 119341 | E18: Email | F18: Retention | G18: 9190.27 | H18: 0.12 | I18: 0.16 | J18: 23 | K18: 1.75 | L18: 0.69 | M18: 38 | N18: 18 | O18: 7 | P18: 1 | Q18: 4275 | R18: IsConfid | S18: ToolConfid | T18: 1 | U18: 9190.27
A19: 8049 | B19: 42 | C19: Female | D19: 127955 | E19: SEO | F19: Retention | G19: 408.69 | H19: 0.2 | I19: 0.11 | J19: 46 | K19: 6.92 | L19: 13.97 | M19: 96 | N19: 17 | O19: 4 | P19: 9 | Q19: 3404 | R19: IsConfid | S19: ToolConfid | T19: 1 | U19: 408.69
A20: 8055 | B20: 37 | C20: Male | D20: 37667 | E20: Email | F20: Consideration | G20: 7856.01 | H20: 0.09 | I20: 0.07 | J20: 22 | K20: 4.61 | L20: 1.98 | M20: 87 | N20: 3 | O20: 8 | P20: 2 | Q20: 1977 | R20: IsConfid | S20: ToolConfid | T20: 1 | U20: 7856.01
A21: 8057 | B21: 64 | C21: Female | D21: 26732 | E21: PPC | F21: Awareness | G21: 7830.39 | H21: 0.04 | I21: 0.12 | J21: 37 | K21: 3.28 | L21: 10.5 | M21: 68 | N21: 5 | O21: 3 | P21: 0 | Q21: 336 | R21: IsConfid | S21: ToolConfid | T21: 1 | U21: 7830.39
A22: 8071 | B22: 59 | C22: Female | D22: 59865 | E22: PPC | F22: Conversion | G22: 3042.86 | H22: 0.3 | I22: 0.14 | J22: 43 | K22: 2.33 | L22: 4.58 | M22: 46 | N22: 4 | O22: 5 | P22: 7 | Q22: 558 | R22: IsConfid | S22: ToolConfid | T22: 1 | U22: 3042.86
A23: 8072 | B23: 21 | C23: Male | D23: 28469 | E23: Email | F23: Consideration | G23: 6536.09 | H23: 0.13 | I23: 0.17 | J23: 44 | K23: 5.41 | L23: 5.74 | M23: 8 | N23: 5 | O23: 5 | P23: 4 | Q23: 2761 | R23: IsConfid | S23: ToolConfid | T23: 1 | U23: 6536.09
A24: 8074 | B24: 35 | C24: Female | D24: 144866 | E24: PPC | F24: Awareness | G24: 6808.22 | H24: 0.06 | I24: 0.09 | J24: 49 | K24: 3.81 | L24: 5.69 | M24: 0 | N24: 8 | O24: 1 | P24: 8 | Q24: 3483 | R24: IsConfid | S24: ToolConfid | T24: 1 | U24: 6808.22
A25: 8084 | B25: 25 | C25: Male | D25: 129122 | E25: Social Media | F25: Consideration | G25: 6979.08 | H25: 0.07 | I25: 0.1 | J25: 16 | K25: 6.24 | L25: 10.67 | M25: 59 | N25: 10 | O25: 6 | P25: 5 | Q25: 928 | R25: IsConfid | S25: ToolConfid | T25: 1 | U25: 6979.08
A26: 8085 | B26: 31 | C26: Female | D26: 52259 | E26: SEO | F26: Awareness | G26: 6053.54 | H26: 0.22 | I26: 0.06 | J26: 25 | K26: 6.49 | L26: 13.54 | M26: 87 | N26: 5 | O26: 1 | P26: 1 | Q26: 1884 | R26: IsConfid | S26: ToolConfid | T26: 1 | U26: 6053.54
A27: 8087 | B27: 57 | C27: Female | D27: 106284 | E27: Email | F27: Awareness | G27: 9033.88 | H27: 0.16 | I27: 0.02 | J27: 43 | K27: 6.34 | L27: 1 | M27: 38 | N27: 6 | O27: 9 | P27: 9 | Q27: 932 | R27: IsConfid | S27: ToolConfid | T27: 1 | U27: 9033.88
A28: 8088 | B28: 38 | C28: Female | D28: 105227 | E28: Email | F28: Awareness | G28: 3027.52 | H28: 0.09 | I28: 0.19 | J28: 6 | K28: 7.77 | L28: 6.03 | M28: 2 | N28: 15 | O28: 6 | P28: 3 | Q28: 3472 | R28: IsConfid | S28: ToolConfid | T28: 1 | U28: 3027.52
... A46: 8131 | B46: 54 | C46: Female | D46: 126384 | E46: Social Media | F46: Conversion | G46: 5210.55 | H46: 0.27 | I46: 0.08 | J46: 35 | K46: 9.39 | L46: 12.59 | M46: 53 | N46: 4 | O46: 6 | P46: 0 | Q46: 3755 | R46: IsConfid | S46: ToolConfid | T46: 1 | U46: 5210.55
A47: 8142 | B47: 31 | C47: Female | D47: 78186 | E47: PPC | F47: Retention | G47: 1508.76 | H47: 0.03 | I47: 0.03 | J47: 38 | K47: 5.53 | L47: 7.24 | M47: 12 | N47: 19 | O47: 0 | P47: 1 | Q47: 1913 | R47: IsConfid | S47: ToolConfid | T47: 0
A48: 8147 | B48: 31 | C48: Male | D48: 126887 | E48: SEO | F48: Conversion | G48: 5141.04 | H48: 0.25 | I48: 0.02 | J48: 36 | K48: 5.64 | L48: 13.77 | M48: 58 | N48: 7 | O48: 7 | P48: 9 | Q48: 3096 | R48: IsConfid | S48: ToolConfid | T48: 1 | U48: 5141.04
A49: 8149 | B49: 44 | C49: Male | D49: 45476 | E49: Social Media | F49: Consideration | G49: 5423.01 | H49: 0.04 | I49: 0.18 | J49: 35 | K49: 3.29 | L49: 3.37 | M49: 71 | N49: 14 | O49: 6 | P49: 7 | Q49: 252 | R49: IsConfid | S49: ToolConfid | T49: 1 | U49: 5423.01
A50: 8156 | B50: 68 | C50: Male | D50: 51653 | E50: Social Media | F50: Awareness | G50: 4506.25 | H50: 0.25 | I50: 0.11 | J50: 7 | K50: 2.54 | L50: 12.72 | M50: 57 | N50: 18 | O50: 4 | P50: 4 | Q50: 2699 | R50: IsConfid | S50: ToolConfid | T50: 1 | U50: 4506.25
A51: 8159 | B51: 66 | C51: Male | D51: 39629 | E51: Referral | F51: Awareness | G51: 1050.92 | H51: 0.15 | I51: 0.09 | J51: 15 | K51: 6.28 | L51: 6.79 | M51: 92 | N51: 11 | O51: 1 | P51: 5 | Q51: 2503 | R51: IsConfid | S51: ToolConfid | T51: 1 | U51: 1050.92
A52: 8165 | B52: 40 | C52: Female | D52: 39322 | E52: SEO | F52: Awareness | G52: 1430.62 | H52: 0.17 | I52: 0.06 | J52: 33 | K52: 6.2 | L52: 10.86 | M52: 19 | N52: 8 | O52: 5 | P52: 0 | Q52: 1775 | R52: IsConfid | S52: ToolConfid | T52: 1 | U52: 1430.62
A53: 8167 | B53: 62 | C53: Female | D53: 135637 | E53: SEO | F53: Awareness | G53: 5970.85 | H53: 0.23 | I53: 0.16 | J53: 39 | K53: 2.82 | L53: 9.62 | M53: 25 | N53: 11 | O53: 8 | P53: 7 | Q53: 927 | R53: IsConfid | S53: ToolConfid | T53: 1 | U53: 5970.85
A54: 8171 | B54: 53 | C54: Male | D54: 122379 | E54: Referral | F54: Conversion | G54: 2205.5 | H54: 0.27 | I54: 0.16 | J54: 26 | K54: 7.76 | L54: 1.27 | M54: 81 | N54: 4 | O54: 6 | P54: 0 | Q54: 3396 | R54: IsConfid | S54: ToolConfid | T54: 1 | U54: 2205.5
A55: 8172 | B55: 30 | C55: Male | D55: 32651 | E55: Email | F55: Consideration | G55: 6079.48 | H55: 0.12 | I55: 0.12 | J55: 18 | K55: 7.74 | L55: 8.4 | M55: 58 | N55: 11 | O55: 2 | P55: 0 | Q55: 3426 | R55: IsConfid | S55: ToolConfid | T55: 1 | U55: 6079.48
A56: 8173 | B56: 49 | C56: Female | D56: 45966 | E56: Referral | F56: Awareness | G56: 9550.16 | H56: 0.24 | I56: 0.05 | J56: 25 | K56: 4.74 | L56: 5.72 | M56: 2 | N56: 11 | O56: 0 | P56: 2 | Q56: 3060 | R56: IsConfid | S56: ToolConfid | T56: 1 | U56: 9550.16
A57: 8181 | B57: 23 | C57: Female | D57: 59727 | E57: SEO | F57: Awareness | G57: 7210.62 | H57: 0.09 | I57: 0.07 | J57: 26 | K57: 7.27 | L57: 1.08 | M57: 29 | N57: 14 | O57: 1 | P57: 9 | Q57: 126 | R57: IsConfid | S57: ToolConfid | T57: 1 | U57: 7210.62
...

Sheet MARKETING DASHBOARD SHEET

Sheet CUSTOMER ANALYTICS DASHBOARD

Sheet  Marketing  pivot sheet
B4: Total ad spend | C4: Average of AdSpend
B5: 1520494.3 | C5: 4781.4286 | F5: Row Labels | G5: Total Ad spend | H5: Total Conversions | I5: Average of ConversionRate | P5: Row Labels | Q5: Sum of WebsiteVisits | R5: Sum of Conversion | U5: CampaignChannel | V5: Sum of Conversion | W5: CPA ($)
F6: Email | G6: 308171.23 | H6: 62 | I6: 0.10720588 | P6: Email | Q6: 1765 | R6: 62 | U6: Email | V6: 62 | W6: 4970.5037
F7: PPC | G7: 326461.13 | H7: 60 | I7: 0.096521739 | P7: PPC | Q7: 1694 | R7: 60 | U7: PPC | V7: 60 | W7: 5441.0188
F8: Referral | G8: 291121.96 | H8: 52 | I8: 0.10226415 | P8: Social Media | Q8: 1669 | R8: 63 | U8: Referral | V8: 52 | W8: 5598.4992
F9: SEO | G9: 300698.83 | H9: 58 | I9: 0.10870968 | P9: SEO | Q9: 1589 | R9: 58 | U9: SEO | V9: 58 | W9: 5184.4626
F10: Social Media | G10: 294041.14 | H10: 63 | I10: 0.11212121 | P10: Referral | Q10: 1309 | R10: 52 | U10: Social Media | V10: 63 | W10: 4667.3197
F11: Grand Total | G11: 1520494.3 | H11: 295 | I11: 0.10537736 | P11: Grand Total | Q11: 8026 | R11: 295
F16: Sum of WebsiteVisits | G16: Sum of EmailOpens | H16: Sum of EmailClicks | I16: Sum of Conversion
B17: Total Conversions | F17: 8026 | G17: 3079 | H17: 1392 | I17: 295
B18: 295
F22: Row Labels | G22: Sum of ORIGINAL CPA
F23: Social Media | G23: 4667.3197
B24: Sum of Blended CPA | F24: Email | G24: 4970.5037
B25: 5154.2179 | F25: SEO | G25: 5184.4626
F26: PPC | G26: 5441.0188
F27: Referral | G27: 5598.4992
F28: Grand Total | G28: 5154.2179
B31: Average of ConversionRate
B32: 0.10537736
B37: Sum of WebsiteVisits
B38: 8026

Sheet copy sheet for marketing analyt
G4: Row Labels | H4: Total Ad spend | I4: =' Marketing pivot sheet'!$H$5 -> Total Conversions | J4: =' Marketing pivot sheet'!$I$5 -> Average of ConversionRate
G5: Email | H5: =' Marketing pivot sheet'!G6 -> 308171.23 | I5: =' Marketing pivot sheet'!H6 -> 62 | J5: =' Marketing pivot sheet'!I6 -> 0.10720588
G6: PPC | H6: =' Marketing pivot sheet'!G7 -> 326461.13 | I6: =' Marketing pivot sheet'!H7 -> 60 | J6: =' Marketing pivot sheet'!I7 -> 0.096521739
G7: Referral | H7: =' Marketing pivot sheet'!G8 -> 291121.96 | I7: =' Marketing pivot sheet'!H8 -> 52 | J7: =' Marketing pivot sheet'!I8 -> 0.10226415
G8: SEO | H8: =' Marketing pivot sheet'!G9 -> 300698.83 | I8: =' Marketing pivot sheet'!H9 -> 58 | J8: =' Marketing pivot sheet'!I9 -> 0.10870968
G9: Social Media | H9: =' Marketing pivot sheet'!G10 -> 294041.14 | I9: =' Marketing pivot sheet'!H10 -> 63 | J9: =' Marketing pivot sheet'!I10 -> 0.11212121
B15: STAGE | C15: TOTAL
B16: Conversions | C16: =' Marketing pivot sheet'!I17 -> 295
B17: Email Clicks | C17: =' Marketing pivot sheet'!H17 -> 1392
B18: Email Opens | C18: =' Marketing pivot sheet'!G17 -> 3079
B19: Website Visits | C19: =' Marketing pivot sheet'!F17 -> 8026

Sheet Customer PIVOT SHEET
B3: Count of CustomerID | F3: Sum of WebsiteVisits | G3: Sum of EmailOpens | H3: Sum of EmailClicks | I3: Sum of Conversion | L3: Row Labels | M3: Average of PagesPerVisit | O3: Row Labels | P3: Count of CustomerID | V3: Age Group | W3: Total Customers | X3: Total Conversions | Y3: Avg Time on Site
B4: 318 | F4: 8026 | G4: 3079 | H4: 1392 | I4: 295 | L4: High | M4: 5.7256637 | O4: 0-3 | P4: 59 | V4: 34-37 | W4: 14 | X4: 13 | Y4: 7.1442857
L5: Low | M5: 5.3235052 | O5: 3-6 | P5: 57 | V5: 30-33 | W5: 18 | X5: 15 | Y5: 6.9883333
L6: Mid | M6: 5.3147222 | O6: 6-9 | P6: 68 | V6: 26-29 | W6: 19 | X6: 17 | Y6: 6.2252632
L7: Grand Total | M7: 5.4634277 | O7: 9-12 | P7: 61 | V7: 58-61 | W7: 21 | X7: 21 | Y7: 6.717619
B8: Sum of Conversion | F8: Row Labels | G8: Count of CustomerID | O8: 12-15 | P8: 73 | V8: 46-49 | W8: 23 | X8: 22 | Y8: 9.1295652
B9: 295 | F9: Female | G9: 187 | O9: Grand Total | P9: 318 | V9: 54-57 | W9: 24 | X9: 23 | Y9: 8.655
F10: Male | G10: 131 | V10: 62-65 | W10: 25 | X10: 25 | Y10: 8.1052
F11: Grand Total | G11: 318 | V11: 18-21 | W11: 27 | X11: 25 | Y11: 8.7496296
B12: Average of PagesPerVisit | V12: 66-69 | W12: 28 | X12: 26 | Y12: 8.62
B13: 5.4634277 | V13: 22-25 | W13: 28 | X13: 24 | Y13: 7.7246429
V14: 50-53 | W14: 28 | X14: 24 | Y14: 8.4325
V15: 38-41 | W15: 31 | X15: 29 | Y15: 7.226129
B16: Average of TimeOnSite | V16: 42-45 | W16: 32 | X16: 31 | Y16: 7.9534375
B17: 7.9056918
B19: Average of LoyaltyPoints
B20: 2441.9371

Sheet COPY SHEET FOR CUSTOMER ANALYTI
B3: Conversion | C3: ='Customer PIVOT SHEET'!I4 -> 295
B4: Email Clicks | C4: ='Customer PIVOT SHEET'!H4 -> 1392
B5: Email Opens | C5: ='Customer PIVOT SHEET'!G4 -> 3079
B6: Website Visits | C6: ='Customer PIVOT SHEET'!F4 -> 8026
